//USING TRY-CATCH
/*
const asyncHandler = (fn) => async (req, res, next) => {
    try {
        await fn(req, res, next);
    } catch (error) {
        res.status(error.send || 500).json({
            success: false,
            message: error.message
        });
    }
}
*/

//USING PROMISES
const asyncHandler = (requestHandler) => {
    return (req, res, next) => {
        Promise.resolve(requestHandler(req, res, next)).catch((err) => next(err))
    }
}

export { asyncHandler }
